[2024-03-01T16:27:12.148+0530] {taskinstance.py:1956} INFO - Dependencies all met for dep_context=non-requeueable deps ti=<TaskInstance: datapipeline_Take4.select_urls scheduled__2024-03-01T10:54:00+00:00 [queued]>
[2024-03-01T16:27:12.166+0530] {taskinstance.py:1956} INFO - Dependencies all met for dep_context=requeueable deps ti=<TaskInstance: datapipeline_Take4.select_urls scheduled__2024-03-01T10:54:00+00:00 [queued]>
[2024-03-01T16:27:12.167+0530] {taskinstance.py:2170} INFO - Starting attempt 1 of 2
[2024-03-01T16:27:12.307+0530] {taskinstance.py:2191} INFO - Executing <Task(PythonOperator): select_urls> on 2024-03-01 10:54:00+00:00
[2024-03-01T16:27:12.330+0530] {standard_task_runner.py:60} INFO - Started process 22115 to run task
[2024-03-01T16:27:12.349+0530] {standard_task_runner.py:87} INFO - Running: ['airflow', 'tasks', 'run', 'datapipeline_Take4', 'select_urls', 'scheduled__2024-03-01T10:54:00+00:00', '--job-id', '107', '--raw', '--subdir', 'DAGS_FOLDER/datapipeline_best(1).py', '--cfg-path', '/tmp/tmpxab87m06']
[2024-03-01T16:27:12.358+0530] {standard_task_runner.py:88} INFO - Job 107: Subtask select_urls
[2024-03-01T16:27:12.537+0530] {task_command.py:423} INFO - Running <TaskInstance: datapipeline_Take4.select_urls scheduled__2024-03-01T10:54:00+00:00 [running]> on host arun-VM
[2024-03-01T16:27:12.919+0530] {taskinstance.py:2480} INFO - Exporting env vars: AIRFLOW_CTX_DAG_OWNER='aa' AIRFLOW_CTX_DAG_ID='datapipeline_Take4' AIRFLOW_CTX_TASK_ID='select_urls' AIRFLOW_CTX_EXECUTION_DATE='2024-03-01T10:54:00+00:00' AIRFLOW_CTX_TRY_NUMBER='1' AIRFLOW_CTX_DAG_RUN_ID='scheduled__2024-03-01T10:54:00+00:00'
[2024-03-01T16:27:12.924+0530] {taskinstance.py:2698} ERROR - Task failed with exception
Traceback (most recent call last):
  File "/home/arun/.local/lib/python3.10/site-packages/airflow/models/taskinstance.py", line 433, in _execute_task
    result = execute_callable(context=context, **execute_callable_kwargs)
  File "/home/arun/.local/lib/python3.10/site-packages/airflow/operators/python.py", line 199, in execute
    return_value = self.execute_callable()
  File "/home/arun/.local/lib/python3.10/site-packages/airflow/operators/python.py", line 216, in execute_callable
    return self.python_callable(*self.op_args, **self.op_kwargs)
TypeError: select_urls() missing 1 required positional argument: 'csvs_list'
[2024-03-01T16:27:12.938+0530] {taskinstance.py:1138} INFO - Marking task as UP_FOR_RETRY. dag_id=datapipeline_Take4, task_id=select_urls, execution_date=20240301T105400, start_date=20240301T105712, end_date=20240301T105712
[2024-03-01T16:27:13.029+0530] {standard_task_runner.py:107} ERROR - Failed to execute job 107 for task select_urls (select_urls() missing 1 required positional argument: 'csvs_list'; 22115)
[2024-03-01T16:27:13.088+0530] {local_task_job_runner.py:234} INFO - Task exited with return code 1
[2024-03-01T16:27:13.149+0530] {taskinstance.py:3280} INFO - 0 downstream tasks scheduled from follow-on schedule check
