[2024-03-04T18:30:18.739+0530] {taskinstance.py:1956} INFO - Dependencies all met for dep_context=non-requeueable deps ti=<TaskInstance: Visualization_DAG.beam_pipeine scheduled__2024-03-04T12:57:00+00:00 [queued]>
[2024-03-04T18:30:18.745+0530] {taskinstance.py:1956} INFO - Dependencies all met for dep_context=requeueable deps ti=<TaskInstance: Visualization_DAG.beam_pipeine scheduled__2024-03-04T12:57:00+00:00 [queued]>
[2024-03-04T18:30:18.745+0530] {taskinstance.py:2170} INFO - Starting attempt 1 of 2
[2024-03-04T18:30:18.767+0530] {taskinstance.py:2191} INFO - Executing <Task(PythonOperator): beam_pipeine> on 2024-03-04 12:57:00+00:00
[2024-03-04T18:30:18.774+0530] {standard_task_runner.py:60} INFO - Started process 12002 to run task
[2024-03-04T18:30:18.778+0530] {standard_task_runner.py:87} INFO - Running: ['airflow', 'tasks', 'run', 'Visualization_DAG', 'beam_pipeine', 'scheduled__2024-03-04T12:57:00+00:00', '--job-id', '204', '--raw', '--subdir', 'DAGS_FOLDER/.ipynb_checkpoints/Analytics_data-checkpoint.py', '--cfg-path', '/tmp/tmpw25s_bb3']
[2024-03-04T18:30:18.778+0530] {standard_task_runner.py:88} INFO - Job 204: Subtask beam_pipeine
[2024-03-04T18:30:18.825+0530] {task_command.py:423} INFO - Running <TaskInstance: Visualization_DAG.beam_pipeine scheduled__2024-03-04T12:57:00+00:00 [running]> on host arun-VM
[2024-03-04T18:30:18.896+0530] {taskinstance.py:2480} INFO - Exporting env vars: AIRFLOW_CTX_DAG_OWNER='admin' AIRFLOW_CTX_DAG_ID='Visualization_DAG' AIRFLOW_CTX_TASK_ID='beam_pipeine' AIRFLOW_CTX_EXECUTION_DATE='2024-03-04T12:57:00+00:00' AIRFLOW_CTX_TRY_NUMBER='1' AIRFLOW_CTX_DAG_RUN_ID='scheduled__2024-03-04T12:57:00+00:00'
[2024-03-04T18:30:18.962+0530] {taskinstance.py:2698} ERROR - Task failed with exception
Traceback (most recent call last):
  File "/home/arun/.local/lib/python3.10/site-packages/airflow/models/taskinstance.py", line 433, in _execute_task
    result = execute_callable(context=context, **execute_callable_kwargs)
  File "/home/arun/.local/lib/python3.10/site-packages/airflow/operators/python.py", line 199, in execute
    return_value = self.execute_callable()
  File "/home/arun/.local/lib/python3.10/site-packages/airflow/operators/python.py", line 216, in execute_callable
    return self.python_callable(*self.op_args, **self.op_kwargs)
  File "/home/arun/airflow/dags/.ipynb_checkpoints/Analytics_data-checkpoint.py", line 97, in beam_pipeline
    | beam.Map(csv_df)
NameError: name 'csv_df' is not defined
[2024-03-04T18:30:18.968+0530] {taskinstance.py:1138} INFO - Marking task as UP_FOR_RETRY. dag_id=Visualization_DAG, task_id=beam_pipeine, execution_date=20240304T125700, start_date=20240304T130018, end_date=20240304T130018
[2024-03-04T18:30:18.990+0530] {standard_task_runner.py:107} ERROR - Failed to execute job 204 for task beam_pipeine (name 'csv_df' is not defined; 12002)
[2024-03-04T18:30:19.002+0530] {local_task_job_runner.py:234} INFO - Task exited with return code 1
[2024-03-04T18:30:19.019+0530] {taskinstance.py:3280} INFO - 0 downstream tasks scheduled from follow-on schedule check
